Workbook

Sheet Consolidado (Funil A)
B1: 10/02/26 a 19/02/26
B2: FE2; FE3; FE6 (tabela consolidada dos 3 fluxos)
B3: Product | D3: Taxa de Conversão | E3: Sale Price | F3: Orders | G3: Total Revenue | H3: OPP/Venda | I3: Operating Profit
B5: Produto 1 - 3 Bottles | C5: - | D5: =F5/$F$8 -> 0.11764706 | E5: 209.94 | F5: 62 | G5: =F5*E5 -> 13016.28 | H5: 141.27 | I5: =H5*F5 -> 8758.74
B6: Produto 1 - 6 Bottles | C6: - | D6: =F6/$F$8 -> 0.75711575 | E6: 299.88 | F6: 399 | G6: =F6*E6 -> 119652.12 | H6: 201.84 | I6: =H6*F6 -> 80534.16
B7: Produto 1 - 2 Bottles | C7: - | D7: =F7/$F$8 -> 0.12523719 | E7: 159.96 | F7: 66 | G7: =F7*E7 -> 10557.36 | H7: 106.13 | I7: =H7*F7 -> 7004.58
B8: 📊 RESUMO FRONTS (FE) | C8: - | D8: - | E8: - | F8: =SUM(F5:F7) -> 527 | G8: =SUM(G5:G7) -> 143225.76 | H8: - | I8: =SUM(I5:I7) -> 96297.48
B10: Up 1 - Backend | C10: - | D10: =F10/F8 -> 0.23719165 | E10: - | F10: =SUM(F11:F16) -> 125 | G10: =SUM(G11:G16) -> 28332.6 | H10: - | I10: =SUM(I11:I16) -> 20303.96
B11: Produto 1 - Special Offer - 6 Bottles | C11: - | D11: =F11/$F$10 -> 0.144 | E11: 239.88 | F11: 18 | G11: =F11*E11 -> 4317.84 | H11: 165.99 | I11: =H11*F11 -> 2987.82
B12: Produto 1 - Special Offer - 3 Bottles | C12: - | D12: =F12/$F$10 -> 0.088 | E12: 149.94 | F12: 11 | G12: =F12*E12 -> 1649.34 | H12: 105.42 | I12: =H12*F12 -> 1159.62
B13: Produto 1 - Special Offer - 9 Bottles | C13: - | D13: =F13/$F$10 -> 0.544 | E13: 269.82 | F13: 68 | G13: =F13*E13 -> 18347.76 | H13: 197.25 | I13: =H13*F13 -> 13413
B14: Produto 1- Special Offer + - 2 Bottles | C14: - | D14: =F14/$F$10 -> 0.024 | E14: 99.96 | F14: 3 | G14: =F14*E14 -> 299.88 | H14: 70.28 | I14: =H14*F14 -> 210.84
B15: Produto 1- Special Offer + - 3 Bottles | C15: - | D15: =F15/$F$10 -> 0.104 | E15: 119.94 | F15: 13 | G15: =F15*E15 -> 1559.22 | H15: 83 | I15: =H15*F15 -> 1079
B16: Produto 1- Special Offer + - 6 Bottles | C16: - | D16: =F16/$F$10 -> 0.096 | E16: 179.88 | F16: 12 | G16: =F16*E16 -> 2158.56 | H16: 121.14 | I16: =H16*F16 -> 1453.68
B18: Up 2 - Backend | C18: - | D18: =F18/F8 -> 0.085388994 | E18: - | F18: =SUM(F19:F24) -> 45 | G18: =SUM(G19:G24) -> 6226.18 | H18: - | I18: =SUM(I19:I24) -> 4228.17
B19: Produto 2 - Special Offer + - 6 Bottles | C19: - | D19: =F19/$F$18 -> 0.022222222 | E19: 119.88 | F19: 1 | G19: =F19*E19 -> 119.88 | H19: 76.23 | I19: =H19*F19 -> 76.23
B20: Produto 2 - Special Offer + - 3 Bottles | C20: - | D20: =F20/$F$18 -> 0.11111111 | E20: 89.94 | F20: 5 | G20: =F20*E20 -> 449.7 | H20: 60.54 | I20: =H20*F20 -> 302.7
B21: Produto 2 - Special Offer + - 2 Bottles | C21: - | D21: =F21/$F$18 -> 0.088888889 | E21: 79.96 | F21: 4 | G21: =F21*E21 -> 319.84 | H21: 55.31 | I21: =H21*F21 -> 221.24
B22: Produto 2- Special Offer - 3 Bottles | C22: - | D22: =F22/$F$18 -> 0.17777778 | E22: 119.94 | F22: 8 | G22: =F22*E22 -> 959.52 | H22: 82.97 | I22: =H22*F22 -> 663.76
B23: Produto 2- Special Offer - 2 Bottles | C23: - | D23: =F23/$F$18 -> 0.13333333 | E23: 99.96 | F23: 6 | G23: =F23*E23 -> 599.76 | H23: 70.26 | I23: =H23*F23 -> 421.56
B24: Produto 2- Special Offer - 6 Bottles | C24: - | D24: =F24/$F$18 -> 0.46666667 | E24: 179.88 | F24: 21 | G24: =F24*E24 -> 3777.48 | H24: 121.08 | I24: =H24*F24 -> 2542.68
B26: Up 3 - Backend | C26: - | D26: =F26/F8 -> 0.049335863 | E26: - | F26: =SUM(F27:F32) -> 26 | G26: =SUM(G28:G32) -> 3847.66 | H26: - | I26: =SUM(I28:I32) -> 2616.4
B27: Produto 3 - Special Offer + - 6 Bottles | C27: - | D27: =F27/$F$26 -> 0 | E27: 119.88 | F27: 0 | G27: =F27*E27 -> 0 | H27: 76.29 | I27: =H27*F27 -> 0
B28: Produto 3 - Special Offer + - 3 Bottles | C28: - | D28: =F28/$F$26 -> 0.038461538 | E28: 89.94 | F28: 1 | G28: =F28*E28 -> 89.94 | H28: 60.57 | I28: =H28*F28 -> 60.57
B29: Produto 3 - Special Offer + - 2 Bottles | C29: - | D29: =F29/$F$26 -> 0.038461538 | E29: 79.96 | F29: 1 | G29: =F29*E29 -> 79.96 | H29: 55.33 | I29: =H29*F29 -> 55.33
B30: Produto 3- Special Offer - 3 Bottles | C30: - | D30: =F30/$F$26 -> 0.15384615 | E30: 119.94 | F30: 4 | G30: =F30*E30 -> 479.76 | H30: 83 | I30: =H30*F30 -> 332
B31: Produto 3- Special Offer - 2 Bottles | C31: - | D31: =F31/$F$26 -> 0.19230769 | E31: 99.96 | F31: 5 | G31: =F31*E31 -> 499.8 | H31: 70.28 | I31: =H31*F31 -> 351.4
B32: Produto 3- Special Offer - 6 Bottles | C32: - | D32: =F32/$F$26 -> 0.57692308 | E32: 179.88 | F32: 15 | G32: =F32*E32 -> 2698.2 | H32: 121.14 | I32: =H32*F32 -> 1817.1
B33: 📊 RESUMO BACKEND (BE) | C33: - | D33: - | E33: - | F33: =SUM(F26,F18,F10) -> 196 | G33: =SUM(G10,G18,G26) -> 38406.44 | H33: - | I33: =SUM(I10,I18,I26) -> 27148.53

Sheet Fluxos Separados por FE (A)
B2: "Dos clientes que optaram pela compra do frontend de 2 potes, esse foi o perfil de compra no restante do funil"
B3: Product | D3: Taxa de Conversão | E3: Sale Price | F3: Orders | G3: Total Revenue | H3: OPP/Venda | I3: Operating Profit
B5: Produto 1 - 2 Bottles | C5: - | D5: =F5/F6 -> 1 | E5: 159.96 | F5: ='Consolidado (Funil A)'!F7 -> 66 | G5: =F5*E5 -> 10557.36 | H5: 106.13 | I5: =H5*F5 -> 7004.58
B6: RESUMO FE2 | C6: - | D6: - | E6: - | F6: =F5 -> 66 | G6: =G5 -> 10557.36 | H6: - | I6: =I5 -> 7004.58
B8: Up 1 - Backend | C8: - | D8: =F8/F6 -> 0.18181818 | F8: =SUM(F9:F11) -> 12 | G8: =SUM(G9:G11) -> 1858.86 | I8: =SUM(I9:I11) -> 1262.96
B9: Produto 1- Special Offer + - 6 Bottles | C9: - | D9: =F9/$F$8 -> 0.66666667 | E9: 179.88 | F9: 8 | G9: =F9*E9 -> 1439.04 | H9: 121.14 | I9: =H9*F9 -> 969.12
B10: Produto 1- Special Offer + - 2 Bottles | C10: - | D10: =F10/$F$8 -> 0.25 | E10: 99.96 | F10: 3 | G10: =F10*E10 -> 299.88 | H10: 70.28 | I10: =H10*F10 -> 210.84
B11: Produto 1- Special Offer + - 3 Bottles | C11: - | D11: =F11/$F$8 -> 0.083333333 | E11: 119.94 | F11: 1 | G11: =F11*E11 -> 119.94 | H11: 83 | I11: =H11*F11 -> 83
B13: Up 2 - Backend | C13: - | D13: =F13/F6 -> 0.03030303 | F13: =SUM(F14:F16) -> 2 | G13: =SUM(G14:G16) -> 199.84 | I13: =SUM(I14:I16) -> 131.54
B14: Produto 2 - Special Offer + - 6 Bottles | C14: - | D14: =F14/F13 -> 0.5 | E14: 119.88 | F14: 1 | G14: =F14*E14 -> 119.88 | H14: 76.23 | I14: =H14*F14 -> 76.23
B15: Produto 2 - Special Offer + - 2 Bottles | C15: - | D15: =F15/F13 -> 0.5 | E15: 79.96 | F15: 1 | G15: =F15*E15 -> 79.96 | H15: 55.31 | I15: =H15*F15 -> 55.31
B16: Produto 2 - Special Offer + - 3 Bottles | C16: - | D16: =F16/$F$37 -> 0 | E16: 89.94 | F16: 0 | G16: =F16*E16 -> 0 | H16: 60.54 | I16: =H16*F16 -> 0
B18: Up 3 - Backend | C18: - | D18: =F18/F6 -> 0.015151515 | F18: =SUM(F19:F21) -> 1 | G18: =G20 -> 89.94 | I18: =I20 -> 60.57
B19: Produto 3 - Special Offer + - 6 Bottles | C19: - | D19: =F19/$F$30 -> 0 | E19: 119.88 | F19: 0 | G19: =F19*E19 -> 0 | H19: 76.29 | I19: =H19*F19 -> 0
B20: Produto 3 - Special Offer + - 3 Bottles | C20: - | D20: =F20/F18 -> 1 | E20: 89.94 | F20: 1 | G20: =F20*E20 -> 89.94 | H20: 60.57 | I20: =H20*F20 -> 60.57
B21: Produto 3 - Special Offer + - 2 Bottles | C21: - | D21: =F21/F18 -> 0 | E21: 79.96 | F21: 0 | G21: =F21*E21 -> 0 | H21: 55.33 | I21: =H21*F21 -> 0
B22: 📊 RESUMO BACKENDS (BE) | C22: - | D22: - | E22: - | F22: =SUM(F8,F13,F18) -> 15 | G22: =SUM(G18,G13,G8) -> 2148.64 | H22: - | I22: =SUM(I18,I13,I8) -> 1455.07
B26: "Dos clientes que optaram pela compra do frontend de 3 potes, esse foi o perfil de compra no restante do funil"
B27: Product | D27: Taxa de Conversão | E27: Sale Price | F27: Orders | G27: Total Revenue | H27: OPP/Venda | I27: Operating Profit
B29: Produto 1 - 3 Bottles | C29: - | D29: =F29/F30 -> 1 | E29: 209.94 | F29: ='Consolidado (Funil A)'!F5 -> 62 | G29: =F29*E29 -> 13016.28 | H29: 141.27 | I29: =H29*F29 -> 8758.74
B30: RESUMO FE3 | C30: - | D30: - | E30: - | F30: =F29 -> 62 | G30: =G29 -> 13016.28 | H30: - | I30: =I29 -> 8758.74
B32: Up 1 - Backend | C32: - | D32: =F32/F30 -> 0.25806452 | E32: - | F32: =SUM(F33:F35) -> 16 | G32: =SUM(G33:G35) -> 2158.8 | I32: =SUM(I33:I35) -> 1480.56
B33: Produto 1- Special Offer + - 3 Bottles | C33: - | D33: =F33/$F$32 -> 0.75 | E33: 119.94 | F33: 12 | G33: =F33*E33 -> 1439.28 | H33: 83 | I33: =H33*F33 -> 996
B34: Produto 1- Special Offer + - 6 Bottles | C34: - | D34: =F34/$F$32 -> 0.25 | E34: 179.88 | F34: 4 | G34: =F34*E34 -> 719.52 | H34: 121.14 | I34: =H34*F34 -> 484.56
B35: Produto 1- Special Offer + - 2 Bottles | C35: - | D35: =F35/$F$32 -> 0 | E35: 99.96 | F35: 0 | G35: =F35*E35 -> 0 | H35: 70.28 | I35: =H35*F35 -> 0
B37: Up 2 - Backend | C37: - | D37: =F37/F30 -> 0.12903226 | E37: - | F37: =SUM(F38:F40) -> 8 | G37: =SUM(G38:G40) -> 689.58 | H37: - | I37: =SUM(I38:I40) -> 468.63
B38: Produto 2 - Special Offer + - 3 Bottles | C38: - | D38: =F38/$F$37 -> 0.625 | E38: 89.94 | F38: 5 | G38: =F38*E38 -> 449.7 | H38: 60.54 | I38: =H38*F38 -> 302.7
B39: Produto 2 - Special Offer + - 2 Bottles | C39: - | D39: =F39/$F$37 -> 0.375 | E39: 79.96 | F39: 3 | G39: =F39*E39 -> 239.88 | H39: 55.31 | I39: =H39*F39 -> 165.93
B40: Produto 2 - Special Offer + - 6 Bottles | C40: - | D40: =F40/$F$37 -> 0 | E40: 119.88 | F40: 0 | G40: =F40*E40 -> 0 | H40: 76.23 | I40: =H40*F40 -> 0
B42: Up 3 - Backend | C42: - | D42: =F42/F30 -> 0.016129032 | E42: - | F42: =SUM(F43:F45) -> 1 | G42: =SUM(G43:G45) -> 79.96 | H42: - | I42: =SUM(I43:I45) -> 55.33
B43: Produto 3 - Special Offer + - 6 Bottles | C43: - | D43: =F43/$F$30 -> 0 | E43: 119.88 | F43: 0 | G43: =F43*E43 -> 0 | H43: 76.29 | I43: =H43*F43 -> 0
B44: Produto 3 - Special Offer + - 3 Bottles | C44: - | D44: =F44/$F$30 -> 0 | E44: 89.94 | F44: 0 | G44: =F44*E44 -> 0 | H44: 60.57 | I44: =H44*F44 -> 0
B45: Produto 3 - Special Offer + - 2 Bottles | C45: - | D45: =F45/F42 -> 1 | E45: 79.96 | F45: 1 | G45: =F45*E45 -> 79.96 | H45: 55.33 | I45: =H45*F45 -> 55.33
B46: 📊 RESUMO BACKENDS (BE) | C46: - | D46: - | E46: - | F46: =SUM(F42,F37,F32) -> 25 | G46: =SUM(G42,G37,G32) -> 2928.34 | H46: - | I46: =SUM(I42,I37,I32) -> 2004.52
B50: "Dos clientes que optaram pela compra do frontend de 6 potes, esse foi o perfil de compra no restante do funil"
B51: Product | D51: Taxa de Conversão | E51: Sale Price | F51: Orders | G51: Total Revenue | H51: OPP/Venda | I51: Operating Profit
B53: Produto 1 - 6 Bottles | C53: - | D53: =F53/F54 -> 1 | E53: 299.88 | F53: ='Consolidado (Funil A)'!F6 -> 399 | G53: =F53*E53 -> 119652.12 | H53: 201.84 | I53: =H53*F53 -> 80534.16
B54: RESUMO FE6 | C54: - | D54: - | E54: - | F54: =F53 -> 399 | G54: =G53 -> 119652.12 | H54: - | I54: =I53 -> 80534.16
B56: Up 1 - Backend | C56: - | D56: =F56/F54 -> 0.24310777 | E56: - | F56: =SUM(F57:F59) -> 97 | G56: =SUM(G57:G59) -> 24314.94 | H56: - | I56: =SUM(I57:I59) -> 17560.44
B57: Produto 1 - Special Offer - 6 Bottles | C57: - | D57: =F57/$F$56 -> 0.18556701 | E57: 239.88 | F57: 18 | G57: =F57*E57 -> 4317.84 | H57: 165.99 | I57: =H57*F57 -> 2987.82
...

Sheet Consolidado (Funil B)
B1: 19/02/26 a 28/02/26
B2: FE2; FE3; FE6 (tabela consolidada dos 3 fluxos)
B3: Product | D3: Taxa de Conversão | E3: Sale Price | F3: Orders | G3: Total Revenue | H3: OPP/Venda | I3: Operating Profit
B5: Produto 1 - 3 Bottles | C5: - | D5: =F5/$F$8 -> 0.29471891 | E5: 209.94 | F5: 173 | G5: =F5*E5 -> 36319.62 | H5: 141.27 | I5: =H5*F5 -> 24439.71
B6: Produto 1 - 6 Bottles | C6: - | D6: =F6/$F$8 -> 0.59965928 | E6: 299.88 | F6: 352 | G6: =F6*E6 -> 105557.76 | H6: 201.84 | I6: =H6*F6 -> 71047.68
B7: Produto 1 - 2 Bottles | C7: - | D7: =F7/$F$8 -> 0.10562181 | E7: 159.96 | F7: 62 | G7: =F7*E7 -> 9917.52 | H7: 106.13 | I7: =H7*F7 -> 6580.06
B8: 📊 RESUMO FRONTS (FE) | C8: - | D8: - | E8: - | F8: =SUM(F5:F7) -> 587 | G8: =SUM(G5:G7) -> 151794.9 | H8: - | I8: =SUM(I5:I7) -> 102067.45
B10: Up 1 - Backend | C10: - | D10: =F10/F8 -> 0.20102215 | E10: - | F10: =SUM(F11:F12) -> 118 | G10: =SUM(G11:G12) -> 34339.2 | H10: - | I10: =SUM(I11:I12) -> 24131.1
B11: Produto 1 - Special Offer - 12 Bottles | C11: - | D11: =F11/$F$10 -> 0.66101695 | E11: 348 | F11: 78 | G11: =F11*E11 -> 27144 | H11: 247.25 | I11: =H11*F11 -> 19285.5
B12: Produto 1- Special Offer + - 6 Bottles | C12: - | D12: =F12/$F$10 -> 0.33898305 | E12: 179.88 | F12: 40 | G12: =F12*E12 -> 7195.2 | H12: 121.14 | I12: =H12*F12 -> 4845.6
B14: Up 2 - Backend | C14: - | D14: =F14/F8 -> 0.063032368 | E14: - | F14: =SUM(F15:F16) -> 37 | G14: =SUM(G15:G16) -> 6355.56 | H14: - | I14: =SUM(I15:I16) -> 4255.71
B15: Produto 2 - Special Offer + - 6 Bottles | C15: - | D15: =F15/$F$14 -> 0.13513514 | E15: 119.88 | F15: 5 | G15: =F15*E15 -> 599.4 | H15: 76.23 | I15: =H15*F15 -> 381.15
B16: Produto 2- Special Offer - 6 Bottles | C16: - | D16: =F16/$F$14 -> 0.86486486 | E16: 179.88 | F16: 32 | G16: =F16*E16 -> 5756.16 | H16: 121.08 | I16: =H16*F16 -> 3874.56
B18: Up 3 - Backend | C18: - | D18: =F18/F8 -> 0.037478705 | E18: - | F18: =SUM(F19:F20) -> 22 | G18: =SUM(G19:G20) -> 3777.36 | H18: - | I18: =SUM(I19:I20) -> 2530.53
B19: Produto 3 - Special Offer + - 6 Bottles | C19: - | D19: =F19/$F$18 -> 0.13636364 | E19: 119.88 | F19: 3 | G19: =F19*E19 -> 359.64 | H19: 76.29 | I19: =H19*F19 -> 228.87
B20: Produto 3- Special Offer - 6 Bottles | C20: - | D20: =F20/$F$18 -> 0.86363636 | E20: 179.88 | F20: 19 | G20: =F20*E20 -> 3417.72 | H20: 121.14 | I20: =H20*F20 -> 2301.66
B21: 📊 RESUMO BACKEND (BE) | C21: - | D21: - | E21: - | F21: =SUM(F18,F14,F10) -> 177 | G21: =SUM(G10,G14,G18) -> 44472.12 | H21: - | I21: =SUM(I10,I14,I18) -> 30917.34

Sheet Fluxos Separados por FE (B)
B2: "Dos clientes que optaram pela compra do frontend de 2 potes, esse foi o perfil de compra no restante do funil"
B3: Product | D3: Taxa de Conversão | E3: Sale Price | F3: Orders | G3: Total Revenue | H3: OPP/Venda | I3: Operating Profit
B5: Produto 1 - 2 Bottles | C5: - | D5: =F5/$F$6 -> 1 | E5: 159.96 | F5: ='Consolidado (Funil B)'!F7 -> 62 | G5: =F5*E5 -> 9917.52 | H5: 106.13 | I5: =H5*F5 -> 6580.06
B6: RESUMO FE2 | C6: - | D6: - | E6: - | F6: =SUM(F5:F5) -> 62 | G6: =SUM(G5:G5) -> 9917.52 | H6: - | I6: =SUM(I5:I5) -> 6580.06
B8: Up 1 - Backend | C8: - | D8: =F8/F6 -> 0.11290323 | E8: - | F8: =SUM(F9:F9) -> 7 | G8: =SUM(G9:G9) -> 1259.16 | H8: - | I8: =SUM(I9:I9) -> 847.98
B9: Produto 1- Special Offer + - 6 Bottles | C9: - | D9: =F9/$F$8 -> 1 | E9: 179.88 | F9: 7 | G9: =F9*E9 -> 1259.16 | H9: 121.14 | I9: =H9*F9 -> 847.98
B11: Up 2 - Backend | C11: - | D11: =F11/F6 -> 0.016129032 | E11: - | F11: =SUM(F12:F12) -> 1 | G11: =SUM(G12:G12) -> 119.88 | H11: - | I11: =SUM(I12:I12) -> 76.23
B12: Produto 2 - Special Offer + - 6 Bottles | C12: - | D12: =F12/$F$11 -> 1 | E12: 119.88 | F12: 1 | G12: =F12*E12 -> 119.88 | H12: 76.23 | I12: =H12*F12 -> 76.23
B14: Up 3 - Backend | C14: - | D14: =F14/F6 -> 0.016129032 | E14: - | F14: =SUM(F15:F15) -> 1 | G14: =SUM(G15:G15) -> 119.88 | H14: - | I14: =I15 -> 76.29
B15: Produto 3 - Special Offer + - 6 Bottles | C15: - | D15: =F15/$F$14 -> 1 | E15: 119.88 | F15: 1 | G15: =F15*E15 -> 119.88 | H15: 76.29 | I15: =H15*F15 -> 76.29
B16: 📊 RESUMO BACKEND (BE) | C16: - | D16: - | E16: - | F16: =SUM(F14,F11,F8) -> 9 | G16: =SUM(G8,G11,G14) -> 1498.92 | H16: - | I16: =SUM(I8,I11,I14) -> 1000.5
B20: "Dos clientes que optaram pela compra do frontend de 3 potes, esse foi o perfil de compra no restante do funil"
B21: Product | D21: Taxa de Conversão | E21: Sale Price | F21: Orders | G21: Total Revenue | H21: OPP/Venda | I21: Operating Profit
B23: Produto 1 - 3 Bottles | C23: - | D23: =F23/$F$24 -> 1 | E23: 209.94 | F23: ='Consolidado (Funil B)'!F5 -> 173 | G23: =F23*E23 -> 36319.62 | H23: 141.27 | I23: =H23*F23 -> 24439.71
B24: RESUMO FE3 | C24: - | D24: - | E24: - | F24: =SUM(F23:F23) -> 173 | G24: =SUM(G23:G23) -> 36319.62 | H24: - | I24: =SUM(I23:I23) -> 24439.71
B26: Up 1 - Backend | C26: - | D26: =F26/F24 -> 0.19075145 | E26: - | F26: =SUM(F27:F27) -> 33 | G26: =SUM(G27:G27) -> 5936.04 | H26: - | I26: =SUM(I27:I27) -> 3997.62
B27: Produto 1- Special Offer + - 6 Bottles | C27: - | D27: =F27/$F$26 -> 1 | E27: 179.88 | F27: 33 | G27: =F27*E27 -> 5936.04 | H27: 121.14 | I27: =H27*F27 -> 3997.62
B29: Up 2 - Backend | C29: - | D29: =F29/F24 -> 0.023121387 | E29: - | F29: =SUM(F30:F30) -> 4 | G29: =SUM(G30:G30) -> 479.52 | H29: - | I29: =SUM(I30:I30) -> 304.92
B30: Produto 2 - Special Offer + - 6 Bottles | C30: - | D30: =F30/$F$29 -> 1 | E30: 119.88 | F30: 4 | G30: =F30*E30 -> 479.52 | H30: 76.23 | I30: =H30*F30 -> 304.92
B32: Up 3 - Backend | C32: - | D32: =F32/F24 -> 0.011560694 | E32: - | F32: =SUM(F33:F33) -> 2 | G32: =SUM(G33:G33) -> 239.76 | H32: - | I32: =I33 -> 152.58
B33: Produto 3 - Special Offer + - 6 Bottles | C33: - | D33: =F33/$F$32 -> 1 | E33: 119.88 | F33: 2 | G33: =F33*E33 -> 239.76 | H33: 76.29 | I33: =H33*F33 -> 152.58
B34: 📊 RESUMO BACKEND (BE) | C34: - | D34: - | E34: - | F34: =SUM(F32,F29,F26) -> 39 | G34: =SUM(G26,G29,G32) -> 6655.32 | H34: - | I34: =SUM(I26,I29,I32) -> 4455.12
B38: "Dos clientes que optaram pela compra do frontend de 6 potes, esse foi o perfil de compra no restante do funil"
B39: Product | D39: Taxa de Conversão | E39: Sale Price | F39: Orders | G39: Total Revenue | H39: OPP/Venda | I39: Operating Profit
B41: Produto 1 - 6 Bottles | C41: - | D41: =F41/$F$42 -> 1 | E41: 299.88 | F41: ='Consolidado (Funil B)'!F6 -> 352 | G41: =F41*E41 -> 105557.76 | H41: 201.84 | I41: =H41*F41 -> 71047.68
B42: RESUMO FE6 | C42: - | D42: - | E42: - | F42: =SUM(F41:F41) -> 352 | G42: =SUM(G41:G41) -> 105557.76 | H42: - | I42: =SUM(I41:I41) -> 71047.68
B44: Up 1 - Backend | C44: - | D44: =F44/F42 -> 0.22159091 | E44: - | F44: =SUM(F45:F45) -> 78 | G44: =SUM(G45:G45) -> 27144 | H44: - | I44: =SUM(I45:I45) -> 19285.5
B45: Produto 1 - Special Offer - 12 Bottles | C45: - | D45: =F45/$F$44 -> 1 | E45: 348 | F45: 78 | G45: =F45*E45 -> 27144 | H45: 247.25 | I45: =H45*F45 -> 19285.5
B47: Up 2 - Backend | C47: - | D47: =F47/F42 -> 0.090909091 | E47: - | F47: =SUM(F48:F48) -> 32 | G47: =SUM(G48:G48) -> 5756.16 | H47: - | I47: =SUM(I48:I48) -> 3874.56
B48: Produto 2- Special Offer - 6 Bottles | C48: - | D48: =F48/$F$47 -> 1 | E48: 179.88 | F48: 32 | G48: =F48*E48 -> 5756.16 | H48: 121.08 | I48: =H48*F48 -> 3874.56
B50: Up 3 - Backend | C50: - | D50: =F50/F42 -> 0.053977273 | E50: - | F50: =SUM(F51:F51) -> 19 | G50: =SUM(G51:G51) -> 3417.72 | H50: - | I50: =SUM(I51:I51) -> 2301.66
B51: Produto 3- Special Offer - 6 Bottles | C51: - | D51: =F51/$F$50 -> 1 | E51: 179.88 | F51: 19 | G51: =F51*E51 -> 3417.72 | H51: 121.14 | I51: =H51*F51 -> 2301.66
B52: 📊 RESUMO BACKEND (BE) | C52: - | D52: - | E52: - | F52: =SUM(F50,F47,F44) -> 129 | G52: =SUM(G44,G47,G50) -> 36317.88 | H52: - | I52: =SUM(I44,I47,I50) -> 25461.72
